<?xml version='1.0'?>
<sdf version='1.8'>
    <model name="arm">
        <static>false</static>
        <self_collide>1</self_collide>
        <link name='base'>
            <pose>0 0 .05 0 0 0</pose>
            <collision name='collision'>
                <geometry>
                    <cylinder>
                        <radius>.5</radius>
                        <length>.1</length>
                    </cylinder>
                </geometry>
            </collision>

            <visual name='visual'>
                <geometry>
                    <cylinder>
                        <radius>.5</radius>
                        <length>.1</length>
                    </cylinder>
                </geometry>
            </visual>
        </link>
        <link name='arm0'>
            <pose>0 0 .125 0 0 0</pose>

            <collision name='collision'>
                <geometry>
                    <cylinder>
                        <radius>.15</radius>
                        <length>.05</length>
                    </cylinder>
                </geometry>
            </collision>

            <visual name='visual'>
                <geometry>
                    <cylinder>
                        <radius>.15</radius>
                        <length>.05</length>
                    </cylinder>
                </geometry>
            </visual>
        </link>
        <link name='arm1'>
            <pose>0 0 1.15 0 0 0</pose>

            <collision name='collision'>
                <geometry>
                    <cylinder>
                        <radius>.1</radius>
                        <length>2.0</length>
                    </cylinder>
                </geometry>
            </collision>

            <visual name='visual'>
                <geometry>
                    <cylinder>
                        <radius>.1</radius>
                        <length>2.0</length>
                    </cylinder>
                </geometry>
            </visual>
        </link>
        <link name="arm2">
            <pose>0 0 2.65 0 0 0</pose>
            <collision name="collision">
                <geometry>
                    <cylinder>
                        <radius>0.1</radius>
                        <length>1.0</length>
                    </cylinder>
                </geometry>
            </collision>
            <visual name="visual">
                <geometry>
                    <cylinder>
                        <radius>0.1</radius>
                        <length>1.0</length>
                    </cylinder>
                </geometry>
            </visual>
        </link>
        <link name="arm3">
            <pose>0 0 3.4 0 0 0</pose>
            <collision name="collision">
                <geometry>
                    <cylinder>
                        <radius>0.1</radius>
                        <length>0.5</length>
                    </cylinder>
                </geometry>
            </collision>
            <visual name="visual">
                <geometry>
                    <cylinder>
                        <radius>0.1</radius>
                        <length>0.5</length>
                    </cylinder>
                </geometry>
            </visual>
        </link>
        <joint type="revolute" name="base_arm0_joint">
            <pose>0 0 -0.025 0 0 0</pose>
            <child>arm0</child>
            <parent>base</parent>
            <axis>
                <xyz>1 0 1</xyz>
            </axis>
        </joint>
        <joint type="revolute" name="arm0_arm1_joint">
            <pose>0 0 -1 0 0 0</pose>
            <child>arm1</child>
            <parent>arm0</parent>
            <axis>
                <xyz>1 0 0</xyz>
            </axis>
        </joint>
        <joint name="arm1_arm2_joint" type="revolute">
            <parent>
                arm1
            </parent>
            <child>
                arm2
            </child>
            <pose>
                0 0 -0.5 0 0 0</pose>
            <axis>
                <xyz>
                    1 0 0
                </xyz>
            </axis>
        </joint>
        <joint name="arm2_arm3_joint" type="revolute">
            <parent>
                arm2
            </parent>
            <child>
                arm3
            </child>
            <pose>
                0 0 -0.25 0 0 0</pose>
            <axis>
                <xyz>
                    1 0 0
                </xyz>
            </axis>
        </joint>
        <plugin name="arm_control" filename="libarm_gazebo.so"/>
    </model>
</sdf>
